<?xml version="1.0"?>
<mujoco model="sphere_robot">
    <compiler inertiafromgeom="true" angle="degree"/>
    <option integrator="RK4"/>
    <option timestep="0.005" iterations="50" solver="Newton" tolerance="1e-10"/>
    <size njmax="1500" nconmax="5000" nstack="5000000"/>

<!--    <asset>-->
<!--        <texture type="skybox" builtin="gradient" rgb1="0.6 0.6 0.6" rgb2="0 0 0" width="512" height="512"/>-->
<!--        <texture name="texplane" type="2d" builtin="checker" rgb1=".1 .0 .1" rgb2=".1 .0 .1" width="512" height="512" mark="cross" markrgb=".8 .8 .8"/>-->
<!--        <material name="matplane" reflectance="0.3" texture="texplane" texrepeat="1 1" texuniform="true"/>-->
<!--    </asset>-->

    <asset>
        <texture type="skybox" builtin="gradient" rgb1="0.3 0.5 0.7" rgb2="0 0 0" width="512" height="512"/>

        <texture name="texplane" type="2d" builtin="checker" rgb1=".2 .3 .4" rgb2=".1 0.15 0.2" width="512" height="512" mark="cross" markrgb=".8 .8 .8"/>

        <texture name="texgeom" type="cube" builtin="flat" mark="cross" width="127" height="1278"
            rgb1="0.8 0.6 0.4" rgb2="0.8 0.6 0.4" markrgb="1 1 1" random="0.01"/>

        <material name="matplane" reflectance="0.3" texture="texplane" texrepeat="1 1" texuniform="true"/>

        <material name="matgeom" texture="texgeom" texuniform="true" rgba="0.8 0.6 .4 1"/>
    </asset>

    <visual>
        <map force="0.1" zfar="30"/>
        <rgba haze="0.15 0.25 0.35 1"/>
        <quality shadowsize="2048"/>
        <global offwidth="800" offheight="800"/>
    </visual>



    <worldbody>
        <geom name="floor" pos="0 0 0" size="0 0 .25" type="plane" material="matplane" condim="3"/>

        <light pos="0 0 6"/>
        <light directional="false" diffuse=".2 .2 .2" specular="0 0 0" pos="0 0 5" dir="0 0 -1" castshadow="false"/>

        <body name="root" pos="0 0 0">
            <freejoint/>
            <geom name="sphere_shell" type="sphere" pos="0 0 0" size=".2 .19" rgba=".0 .0 .0 .2" mass="1" group="1"/>

            <body>
                <joint name="shell" type="ball"/>
                <geom name="bearing1" pos="0      -0.167 -0.03" size="0.01" mass="0.9"/>
                <geom name="line1" type="cylinder" fromto="0       -0.15 -0.03    0     -0.167 -0.03" size="0.005"/>

                <geom name="bearing2" pos="0.1472  0.085 -0.03" size="0.01" mass="0.9"/>
                <geom name="line2" type="cylinder" fromto="0.1299  0.075 -0.03    0.1472 0.085 -0.03" size="0.005"/>

                <geom name="bearing3" pos="-0.1472 0.085 -0.03" size="0.01" mass="0.9"/>
                <geom name="line3" type="cylinder" fromto="-0.1299 0.075 -0.03   -0.1472 0.085 -0.03" size="0.005"/>

                <body>
                    <geom name="platform" type="cylinder" pos="0 0 -0.03" size=".15 .005" rgba=".0 .0 .3 .5" mass="3" group="1"/>
<!--                    <geom name="dasd" type="sphere" pos="0.1 -0.1 -0.02" size="0.01" mass="0.2"/>-->
                </body>

                <body>
                    <joint name="platform_with_fork" type="hinge" axis="0 0 1"/>

                    <geom name="fork0" type="capsule" fromto="0 0 -0.03  0 0 -0.07" size="0.01" mass="0.1" group="0.01"/>
                    <geom name="link_f1_f2" type="capsule" fromto="-0.03 0 -0.07   0.03 0 -0.07" size="0.01" mass="0.001" group="1"/>
                    <geom name="fork1" type="capsule" fromto="-0.03 0 -0.07  -0.03 0 -0.16" size="0.01" mass="0.01" group="1"/>
                    <geom name="fork2" type="capsule" fromto="0.03 0 -0.07  0.03 0 -0.16" size="0.01" mass="0.01" group="1"/>
                    <geom name="wheel_axis" type="cylinder" fromto="-0.03 0 -0.15  0.03 0 -0.15" size="0.005"/>

                     <body name="wheel">
                        <joint name="wheel_motor" type="hinge" axis="1 0 0"/>
                        <geom name="wheel_" type="cylinder" fromto="-0.008 0 -0.15  0.008 0 -0.15" size="0.049 0.005"/>
                     </body>

                </body>
            </body>
        </body>

    </worldbody>


    <equality>
        <connect anchor="0 0 2" body1="root" body2="wheel" name="equality_constraint"/>
    </equality>

<!--    <equality>-->
<!--        <joint joint1="" name="equality_constraint"/>-->
<!--    </equality>-->
    <actuator>
        <motor name="platform_with_fork" gear="5" joint="platform_with_fork"/>
        <motor name="wheel_motor" gear="5" joint="wheel_motor"/>
    </actuator>
</mujoco>
